Workbook
Name Slicer_Diabetes_Status: #N/A
Name Slicer_Weight_Status: #N/A

Sheet Customer Names
A1: Customer ID | B1: name | C1: Title | D1: First Name | E1: Last Name
A2: Id1 | B2: Hawks, Ms. Kelly | C2: Ms | D2: Kelly | E2: Hawks
A3: Id2 | B3: Lehner, Mr. Matthew D | C3: Mr | D3: Matthew D | E3: Lehner
A4: Id3 | B4: Lu, Mr. Phil | C4: Mr | D4: Phil | E4: Lu
A5: Id4 | B5: Osborne, Ms. Kelsey | C5: Ms | D5: Kelsey | E5: Osborne
A6: Id5 | B6: Kadala, Ms. Kristyn | C6: Ms | D6: Kristyn | E6: Kadala
A7: Id6 | B7: Baker, Mr. Russell B. | C7: Mr | D7: Russell B | E7: Baker
A8: Id7 | B8: Macpherson, Mr. Scott | C8: Mr | D8: Scott | E8: Macpherson
A9: Id8 | B9: Hallman, Mr. Stephen | C9: Mr | D9: Stephen | E9: Hallman
A10: Id9 | B10: Moran, Mr. Patrick R. | C10: Mr | D10: Patrick R | E10: Moran
A11: Id10 | B11: Benner, Ms. Brooke N. | C11: Ms | D11: Brooke N | E11: Benner
A12: Id11 | B12: Fierro Vargas, Ms. Paola Andrea | C12: Ms | D12: Paola Andrea | E12: Fierro Vargas
... A72: Id71 | B72: Turner, Mr. Jeff | C72: Mr | D72: Jeff | E72: Turner
A73: Id72 | B73: Rangel, Mr. Elenilton V. Sr. | C73: Mr | D73: Elenilton V | E73: Rangel | F73: Sr
A74: Id73 | B74: Lacey, Ms. Maurya | C74: Ms | D74: Maurya | E74: Lacey
A75: Id74 | B75: Stiger, Ms. Samantha C | C75: Ms | D75: Samantha C | E75: Stiger
A76: Id75 | B76: Caldwell, Ms. Bethany A | C76: Ms | D76: Bethany A | E76: Caldwell
A77: Id76 | B77: Marmillod, Mr. Yves | C77: Mr | D77: Yves | E77: Marmillod
A78: Id77 | B78: Cloutier-Simons, Ms. Danielle | C78: Ms | D78: Danielle | E78: Cloutier-Simons
A79: Id78 | B79: Vegas, Ms. Julia | C79: Ms | D79: Julia | E79: Vegas
A80: Id79 | B80: Cochran, Mr. Joshua | C80: Mr | D80: Joshua | E80: Cochran
A81: Id80 | B81: Holtzapple, Ms. Jennifer | C81: Ms | D81: Jennifer | E81: Holtzapple
A82: Id81 | B82: Meyer, Ms. Gwen M. | C82: Ms | D82: Gwen M | E82: Meyer
A83: Id82 | B83: Brickley, Mr. Patrick | C83: Mr | D83: Patrick | E83: Brickley
A84: Id83 | B84: Magee, Ms. Kate | C84: Ms | D84: Kate | E84: Magee
A85: Id84 | B85: Thoma, Mr. Kevin | C85: Mr | D85: Kevin | E85: Thoma
... A188: Id187 | B188: Dublin, Mr. Andrew P | C188: Mr | D188: Andrew P | E188: Dublin
A189: Id188 | B189: Cleland, Mr. George M. V | C189: Mr | D189: George M | E189: Cleland | F189: V
A190: Id189 | B190: Evans, Ms. Sarah | C190: Ms | D190: Sarah | E190: Evans
A191: Id190 | B191: Boyd, Ms. Lara | C191: Ms | D191: Lara | E191: Boyd
A192: Id191 | B192: Roulier, Mr. Sebastien | C192: Mr | D192: Sebastien | E192: Roulier
A193: Id192 | B193: Mullins, Mr. Padraig | C193: Mr | D193: Padraig | E193: Mullins
A194: Id193 | B194: Hofmann, Ms. Heather | C194: Ms | D194: Heather | E194: Hofmann
A195: Id194 | B195: Garcia Garcia, Mr. Jorge | C195: Mr | D195: Jorge | E195: Garcia Garcia
A196: Id195 | B196: Klecker, Mr. Jack R | C196: Mr | D196: Jack R | E196: Klecker
A197: Id196 | B197: Cancre, Mr. Felix | C197: Mr | D197: Felix | E197: Cancre
A198: Id197 | B198: Denucci, Mr. Christopher C | C198: Mr | D198: Christopher C | E198: Denucci
A199: Id198 | B199: Saldana, Mr. Jesse | C199: Mr | D199: Jesse | E199: Saldana
A200: Id199 | B200: Weinberg, Ms. Jill | C200: Ms | D200: Jill | E200: Weinberg
A201: Id200 | B201: Walsh, Mr. William | C201: Mr | D201: William | E201: Walsh
...

Sheet Medical Examinations
A1: Customer ID | B1: BMI | C1: HBA1C | D1: Heart Issues | E1: Any Transplants | F1: Cancer history | G1: NumberOfMajorSurgeries | H1: smoker | I1: Weight Status | J1: Diabetes Status
A2: Id1 | B2: 47.41 | C2: 7.47 | D2: No | E2: No | F2: No | G2: 0 | H2: Yes | I2: =IF(B2<18.5,"UnderWeight",IF(B2<24.9,"NormalWeight",IF(B2<29.9,"OverWeight","Obesity"))) -> Obesity | J2: =IF(C2<5.7,"Normal",IF(C2<6.4,"Prediabetes","Diabetes")) -> Diabetes
A3: Id2 | B3: 30.36 | C3: 5.77 | D3: No | E3: No | F3: No | G3: 0 | H3: Yes | I3: =IF(B3<18.5,"UnderWeight",IF(B3<24.9,"NormalWeight",IF(B3<29.9,"OverWeight","Obesity"))) -> Obesity | J3: =IF(C3<5.7,"Normal",IF(C3<6.4,"Prediabetes","Diabetes")) -> Prediabetes | K3: Frequent value | M3: =COUNTIF(H2:H2336,"yes") -> 488
A4: Id3 | B4: 34.485 | C4: 11.87 | D4: Yes | E4: No | F4: No | G4: 2 | H4: Yes | I4: =IF(B4<18.5,"UnderWeight",IF(B4<24.9,"NormalWeight",IF(B4<29.9,"OverWeight","Obesity"))) -> Obesity | J4: =IF(C4<5.7,"Normal",IF(C4<6.4,"Prediabetes","Diabetes")) -> Diabetes | M4: =COUNTIF(H:H,"No") -> 1847
A5: Id4 | B5: 38.095 | C5: 6.05 | D5: No | E5: No | F5: No | G5: 0 | H5: Yes | I5: =IF(B5<18.5,"UnderWeight",IF(B5<24.9,"NormalWeight",IF(B5<29.9,"OverWeight","Obesity"))) -> Obesity | J5: =IF(C5<5.7,"Normal",IF(C5<6.4,"Prediabetes","Diabetes")) -> Prediabetes
A6: Id5 | B6: 35.53 | C6: 5.45 | D6: No | E6: No | F6: No | G6: 0 | H6: Yes | I6: =IF(B6<18.5,"UnderWeight",IF(B6<24.9,"NormalWeight",IF(B6<29.9,"OverWeight","Obesity"))) -> Obesity | J6: =IF(C6<5.7,"Normal",IF(C6<6.4,"Prediabetes","Diabetes")) -> Normal
A7: Id6 | B7: 32.8 | C7: 6.59 | D7: No | E7: No | F7: No | G7: 0 | H7: Yes | I7: =IF(B7<18.5,"UnderWeight",IF(B7<24.9,"NormalWeight",IF(B7<29.9,"OverWeight","Obesity"))) -> Obesity | J7: =IF(C7<5.7,"Normal",IF(C7<6.4,"Prediabetes","Diabetes")) -> Diabetes
A8: Id7 | B8: 36.4 | C8: 6.07 | D8: No | E8: No | F8: No | G8: 0 | H8: Yes | I8: =IF(B8<18.5,"UnderWeight",IF(B8<24.9,"NormalWeight",IF(B8<29.9,"OverWeight","Obesity"))) -> Obesity | J8: =IF(C8<5.7,"Normal",IF(C8<6.4,"Prediabetes","Diabetes")) -> Prediabetes
A9: Id8 | B9: 36.96 | C9: 7.93 | D9: No | E9: No | F9: No | G9: 3 | H9: Yes | I9: =IF(B9<18.5,"UnderWeight",IF(B9<24.9,"NormalWeight",IF(B9<29.9,"OverWeight","Obesity"))) -> Obesity | J9: =IF(C9<5.7,"Normal",IF(C9<6.4,"Prediabetes","Diabetes")) -> Diabetes
A10: Id9 | B10: 41.14 | C10: 9.58 | D10: Yes | E10: No | F10: Yes | G10: 1 | H10: Yes | I10: =IF(B10<18.5,"UnderWeight",IF(B10<24.9,"NormalWeight",IF(B10<29.9,"OverWeight","Obesity"))) -> Obesity | J10: =IF(C10<5.7,"Normal",IF(C10<6.4,"Prediabetes","Diabetes")) -> Diabetes
A11: Id10 | B11: 38.06 | C11: 10.79 | D11: No | E11: No | F11: No | G11: 0 | H11: Yes | I11: =IF(B11<18.5,"UnderWeight",IF(B11<24.9,"NormalWeight",IF(B11<29.9,"OverWeight","Obesity"))) -> Obesity | J11: =IF(C11<5.7,"Normal",IF(C11<6.4,"Prediabetes","Diabetes")) -> Diabetes
A12: Id11 | B12: 37.7 | C12: 5.96 | D12: Yes | E12: No | F12: No | G12: 2 | H12: Yes | I12: =IF(B12<18.5,"UnderWeight",IF(B12<24.9,"NormalWeight",IF(B12<29.9,"OverWeight","Obesity"))) -> Obesity | J12: =IF(C12<5.7,"Normal",IF(C12<6.4,"Prediabetes","Diabetes")) -> Prediabetes
A13: Id12 | B13: 42.13 | C13: 11.9 | D13: No | E13: No | F13: No | G13: 0 | H13: Yes | I13: =IF(B13<18.5,"UnderWeight",IF(B13<24.9,"NormalWeight",IF(B13<29.9,"OverWeight","Obesity"))) -> Obesity | J13: =IF(C13<5.7,"Normal",IF(C13<6.4,"Prediabetes","Diabetes")) -> Diabetes
A14: Id13 | B14: 40.92 | C14: 8.41 | D14: No | E14: No | F14: No | G14: 0 | H14: Yes | I14: =IF(B14<18.5,"UnderWeight",IF(B14<24.9,"NormalWeight",IF(B14<29.9,"OverWeight","Obesity"))) -> Obesity | J14: =IF(C14<5.7,"Normal",IF(C14<6.4,"Prediabetes","Diabetes")) -> Diabetes
A15: Id14 | B15: 40.565 | C15: 7.02 | D15: No | E15: No | F15: No | G15: 0 | H15: Yes | I15: =IF(B15<18.5,"UnderWeight",IF(B15<24.9,"NormalWeight",IF(B15<29.9,"OverWeight","Obesity"))) -> Obesity | J15: =IF(C15<5.7,"Normal",IF(C15<6.4,"Prediabetes","Diabetes")) -> Diabetes
A16: Id15 | B16: 36.385 | C16: 7.59 | D16: Yes | E16: No | F16: No | G16: 2 | H16: Yes | I16: =IF(B16<18.5,"UnderWeight",IF(B16<24.9,"NormalWeight",IF(B16<29.9,"OverWeight","Obesity"))) -> Obesity | J16: =IF(C16<5.7,"Normal",IF(C16<6.4,"Prediabetes","Diabetes")) -> Diabetes
... A2071: Id2070 | B2071: 17.3 | C2071: 4.75 | D2071: No | E2071: No | F2071: No | G2071: 0 | H2071: No | I2071: =IF(B2071<18.5,"UnderWeight",IF(B2071<24.9,"NormalWeight",IF(B2071<29.9,"OverWeight","Obesity"))) -> UnderWeight | J2071: =IF(C2071<5.7,"Normal",IF(C2071<6.4,"Prediabetes","Diabetes")) -> Normal
A2072: Id2071 | B2072: 35.625 | C2072: 4.68 | D2072: Yes | E2072: No | F2072: Yes | G2072: 1 | H2072: No
A2073: Id2072 | B2073: 20.235 | C2073: 6.17 | D2073: Yes | E2073: yes | F2073: No | G2073: 2 | H2073: No
A2074: Id2073 | B2074: 27.55 | C2074: 4.56 | D2074: Yes | E2074: No | F2074: Yes | G2074: 1 | H2074: No
A2075: Id2074 | B2075: 17.97 | C2075: 6.3 | D2075: No | E2075: No | F2075: No | G2075: 0 | H2075: No
A2076: Id2075 | B2076: 29.98 | C2076: 6.03 | D2076: No | E2076: yes | F2076: No | G2076: 1 | H2076: No
A2077: Id2076 | B2077: 33.66 | C2077: 4.2 | D2077: Yes | E2077: No | F2077: No | G2077: 1 | H2077: No
A2078: Id2077 | B2078: 32.67 | C2078: 5.61 | D2078: Yes | E2078: No | F2078: No | G2078: 1 | H2078: No
A2079: Id2078 | B2079: 30.5 | C2079: 5.88 | D2079: Yes | E2079: No | F2079: No | G2079: 1 | H2079: No
A2080: Id2079 | B2080: 23.1 | C2080: 5.92 | D2080: Yes | E2080: No | F2080: No | G2080: 1 | H2080: No
A2081: Id2080 | B2081: 39.49 | C2081: 4.81 | D2081: No | E2081: No | F2081: No | G2081: 1 | H2081: No
A2082: Id2081 | B2082: 33.99 | C2082: 4.55 | D2082: No | E2082: No | F2082: No | G2082: 1 | H2082: No
A2083: Id2082 | B2083: 27.72 | C2083: 6.43 | D2083: No | E2083: No | F2083: No | G2083: 1 | H2083: No
... A2336: Id2335 | B2336: 17.58 | C2336: 4.51 | D2336: No | E2336: No | F2336: No | G2336: 1 | H2336: No

Sheet Hospitalisation Details
A1: Customer ID | B1: year | C1: year | D1: month | E1: date | F1: children | G1: charges | H1: Hospital tier | I1: City tier | J1: State ID | K1: State ID | L1: Date of Birth | M1: Age
A2: Id2335 | B2: 1992 | C2: =IF(B2="?",ROUND(AVERAGE(B:B),0),B2) -> 1992 | D2: Jul | E2: 9 | F2: 0 | G2: 563.84 | H2: tier - 2 | I2: tier - 3 | J2: =IF(K2="?","Unknown",K2) -> R1013 | K2: R1013 | L2: =CONCATENATE(E2,"-",D2,"-",C2) -> 9-Jul-1992 | M2: =DATEDIF(L2,DATE(2023,6,8),"Y") -> 30 | O2: No.of Missing values with '?' | Q2: =COUNTIF(A:K,"?") -> 10 | S2: =COUNTIF(J2:J2344,"?") -> 0
A3: Id2334 | B3: 1992 | C3: =IF(B3="?",ROUND(AVERAGE(B:B),0),B3) -> 1992 | D3: Nov | E3: 30 | F3: 0 | G3: 570.62 | H3: tier - 2 | I3: tier - 1 | J3: =IF(K3="?","Unknown",K3) -> R1013 | K3: R1013 | L3: =CONCATENATE(E3,"-",D3,"-",C3) -> 30-Nov-1992 | M3: =DATEDIF(L3,DATE(2023,6,8),"Y") -> 30 | N3: Hospital tier | O3: =COUNTIF(H2:H2344,"tier - 2") -> 1340
A4: Id2333 | B4: 1993 | C4: =IF(B4="?",ROUND(AVERAGE(B:B),0),B4) -> 1993 | D4: Jun | E4: 30 | F4: 0 | G4: 600 | H4: tier - 2 | I4: tier - 1 | J4: =IF(K4="?","Unknown",K4) -> R1013 | K4: R1013 | L4: =CONCATENATE(E4,"-",D4,"-",C4) -> 30-Jun-1993 | M4: =DATEDIF(L4,DATE(2023,6,8),"Y") -> 29 | O4: =COUNTIF(H2:H2344,"tier - 3") -> 694
A5: Id2332 | B5: 1992 | C5: =IF(B5="?",ROUND(AVERAGE(B:B),0),B5) -> 1992 | D5: Sep | E5: 13 | F5: 0 | G5: 604.54 | H5: tier - 3 | I5: tier - 3 | J5: =IF(K5="?","Unknown",K5) -> R1013 | K5: R1013 | L5: =CONCATENATE(E5,"-",D5,"-",C5) -> 13-Sep-1992 | M5: =DATEDIF(L5,DATE(2023,6,8),"Y") -> 30 | O5: =COUNTIF(H2:H2344,"tier - 1") -> 309
A6: Id2331 | B6: 1998 | C6: =IF(B6="?",ROUND(AVERAGE(B:B),0),B6) -> 1998 | D6: Jul | E6: 27 | F6: 0 | G6: 637.26 | H6: tier - 3 | I6: tier - 3 | J6: =IF(K6="?","Unknown",K6) -> R1013 | K6: R1013 | L6: =CONCATENATE(E6,"-",D6,"-",C6) -> 27-Jul-1998 | M6: =DATEDIF(L6,DATE(2023,6,8),"Y") -> 24 | N6: City tier | O6: =COUNTIF(I2:I2344,"tier - 3") -> 796
A7: Id2330 | B7: 2001 | C7: =IF(B7="?",ROUND(AVERAGE(B:B),0),B7) -> 2001 | D7: Nov | E7: 20 | F7: 0 | G7: 646.14 | H7: tier - 3 | I7: tier - 3 | J7: =IF(K7="?","Unknown",K7) -> R1012 | K7: R1012 | L7: =CONCATENATE(E7,"-",D7,"-",C7) -> 20-Nov-2001 | M7: =DATEDIF(L7,DATE(2023,6,8),"Y") -> 21 | O7: =COUNTIF(I2:I22344,"tier - 2") -> 813
A8: Id2329 | B8: 1993 | C8: =IF(B8="?",ROUND(AVERAGE(B:B),0),B8) -> 1993 | D8: Jun | E8: 1 | F8: 0 | G8: 650 | H8: tier - 3 | I8: tier - 3 | J8: =IF(K8="?","Unknown",K8) -> R1013 | K8: R1013 | L8: =CONCATENATE(E8,"-",D8,"-",C8) -> 1-Jun-1993 | M8: =DATEDIF(L8,DATE(2023,6,8),"Y") -> 30 | O8: =COUNTIF(I2:I2344,"tier - 1") -> 734
A9: Id2328 | B9: 1995 | C9: =IF(B9="?",ROUND(AVERAGE(B:B),0),B9) -> 1995 | D9: Jul | E9: 4 | F9: 0 | G9: 650 | H9: tier - 3 | I9: tier - 3 | J9: =IF(K9="?","Unknown",K9) -> R1013 | K9: R1013 | L9: =CONCATENATE(E9,"-",D9,"-",C9) -> 4-Jul-1995 | M9: =DATEDIF(L9,DATE(2023,6,8),"Y") -> 27
A10: Id2327 | B10: 2002 | C10: =IF(B10="?",ROUND(AVERAGE(B:B),0),B10) -> 2002 | D10: Nov | E10: 29 | F10: 0 | G10: 668 | H10: tier - 3 | I10: tier - 2 | J10: =IF(K10="?","Unknown",K10) -> R1012 | K10: R1012 | L10: =CONCATENATE(E10,"-",D10,"-",C10) -> 29-Nov-2002 | M10: =DATEDIF(L10,DATE(2023,6,8),"Y") -> 20
A11: Id2326 | B11: 1997 | C11: =IF(B11="?",ROUND(AVERAGE(B:B),0),B11) -> 1997 | D11: Nov | E11: 9 | F11: 0 | G11: 670 | H11: tier - 3 | I11: tier - 3 | J11: =IF(K11="?","Unknown",K11) -> R1013 | K11: R1013 | L11: =CONCATENATE(E11,"-",D11,"-",C11) -> 9-Nov-1997 | M11: =DATEDIF(L11,DATE(2023,6,8),"Y") -> 25
A12: Id2325 | B12: 2001 | C12: =IF(B12="?",ROUND(AVERAGE(B:B),0),B12) -> 2001 | D12: Sep | E12: 12 | F12: 0 | G12: 687.54 | H12: tier - 3 | I12: tier - 2 | J12: =IF(K12="?","Unknown",K12) -> R1013 | K12: R1013 | L12: =CONCATENATE(E12,"-",D12,"-",C12) -> 12-Sep-2001 | M12: =DATEDIF(L12,DATE(2023,6,8),"Y") -> 21
A13: Id2324 | B13: 1999 | C13: =IF(B13="?",ROUND(AVERAGE(B:B),0),B13) -> 1999 | D13: Dec | E13: 26 | F13: 0 | G13: 700 | H13: tier - 2 | I13: tier - 3 | J13: =IF(K13="?","Unknown",K13) -> R1013 | K13: R1013 | L13: =CONCATENATE(E13,"-",D13,"-",C13) -> 26-Dec-1999 | M13: =DATEDIF(L13,DATE(2023,6,8),"Y") -> 23
A14: Id2323 | B14: 1999 | C14: =IF(B14="?",ROUND(AVERAGE(B:B),0),B14) -> 1999 | D14: Dec | E14: 14 | F14: 0 | G14: 722.99 | H14: tier - 3 | I14: tier - 1 | J14: =IF(K14="?","Unknown",K14) -> R1013 | K14: R1013 | L14: =CONCATENATE(E14,"-",D14,"-",C14) -> 14-Dec-1999 | M14: =DATEDIF(L14,DATE(2023,6,8),"Y") -> 23
A15: Id2322 | B15: 2002 | C15: =IF(B15="?",ROUND(AVERAGE(B:B),0),B15) -> 2002 | D15: Sep | E15: 19 | F15: 0 | G15: 750 | H15: tier - 3 | I15: tier - 1 | J15: =IF(K15="?","Unknown",K15) -> R1012 | K15: R1012 | L15: =CONCATENATE(E15,"-",D15,"-",C15) -> 19-Sep-2002 | M15: =DATEDIF(L15,DATE(2023,6,8),"Y") -> 20
A16: Id2321 | B16: 1993 | C16: =IF(B16="?",ROUND(AVERAGE(B:B),0),B16) -> 1993 | D16: Aug | E16: 9 | F16: 0 | G16: 760 | H16: tier - 3 | I16: tier - 1 | J16: =IF(K16="?","Unknown",K16) -> R1013 | K16: R1013 | L16: =CONCATENATE(E16,"-",D16,"-",C16) -> 9-Aug-1993 | M16: =DATEDIF(L16,DATE(2023,6,8),"Y") -> 29
A17: Id2320 | B17: 1996 | C17: =IF(B17="?",ROUND(AVERAGE(B:B),0),B17) -> 1996 | D17: Oct | E17: 22 | F17: 0 | G17: 760 | H17: tier - 3 | I17: tier - 3 | J17: =IF(K17="?","Unknown",K17) -> R1013 | K17: R1013 | L17: =CONCATENATE(E17,"-",D17,"-",C17) -> 22-Oct-1996 | M17: =DATEDIF(L17,DATE(2023,6,8),"Y") -> 26
A18: Id2319 | B18: 1993 | C18: =IF(B18="?",ROUND(AVERAGE(B:B),0),B18) -> 1993 | D18: Jun | E18: 28 | F18: 0 | G18: 770 | H18: tier - 3 | I18: tier - 3 | J18: =IF(K18="?","Unknown",K18) -> R1013 | K18: R1013 | L18: =CONCATENATE(E18,"-",D18,"-",C18) -> 28-Jun-1993 | M18: =DATEDIF(L18,DATE(2023,6,8),"Y") -> 29
A19: Id2318 | B19: 1996 | C19: =IF(B19="?",ROUND(AVERAGE(B:B),0),B19) -> 1996 | D19: Sep | E19: 18 | F19: 0 | G19: 770.38 | H19: tier - 3 | I19: tier - 2 | J19: =IF(K19="?","Unknown",K19) -> R1012 | K19: R1012 | L19: =CONCATENATE(E19,"-",D19,"-",C19) -> 18-Sep-1996 | M19: =DATEDIF(L19,DATE(2023,6,8),"Y") -> 26
A20: Id2317 | B20: 1995 | C20: =IF(B20="?",ROUND(AVERAGE(B:B),0),B20) -> 1995 | D20: Dec | E20: 7 | F20: 0 | G20: 773.54 | H20: tier - 3 | I20: tier - 2 | J20: =IF(K20="?","Unknown",K20) -> R1013 | K20: R1013 | L20: =CONCATENATE(E20,"-",D20,"-",C20) -> 7-Dec-1995 | M20: =DATEDIF(L20,DATE(2023,6,8),"Y") -> 27
... A1050: Id1290 | B1050: 1977 | C1050: =IF(B1050="?",ROUND(AVERAGE(B:B),0),B1050) -> 1977 | D1050: Jul | E1050: 26 | F1050: 2 | G1050: 8527.53 | H1050: tier - 2 | I1050: tier - 2 | J1050: =IF(K1050="?","Unknown",K1050) -> R1013 | K1050: R1013 | L1050: =CONCATENATE(E1050,"-",D1050,"-",C1050) -> 26-Jul-1977 | M1050: =DATEDIF(L1050,DATE(2023,6,8),"Y") -> 45
A1051: Id1289 | B1051: ? | C1051: =IF(B1051="?",ROUND(AVERAGE(B:B),0),B1051) -> 1983 | D1051: Jul | E1051: 24 | F1051: 0 | G1051: 8534.67 | H1051: tier - 2 | I1051: tier - 3 | J1051: =IF(K1051="?","Unknown",K1051) -> R1024 | K1051: R1024 | L1051: =CONCATENATE(E1051,"-",D1051,"-",C1051) -> 24-Jul-1983 | M1051: =DATEDIF(L1051,DATE(2023,6,8),"Y") -> 39
A1052: Id1288 | B1052: 1981 | C1052: =IF(B1052="?",ROUND(AVERAGE(B:B),0),B1052) -> 1981 | D1052: Dec | E1052: 27 | F1052: 3 | G1052: 8538.29 | H1052: tier - 2 | I1052: tier - 3 | J1052: =IF(K1052="?","Unknown",K1052) -> R1024 | K1052: R1024 | L1052: =CONCATENATE(E1052,"-",D1052,"-",C1052) -> 27-Dec-1981 | M1052: =DATEDIF(L1052,DATE(2023,6,8),"Y") -> 41
A1053: Id1287 | B1053: 1975 | C1053: =IF(B1053="?",ROUND(AVERAGE(B:B),0),B1053) -> 1975 | D1053: Nov | E1053: 6 | F1053: 1 | G1053: 8539.67 | H1053: tier - 2 | I1053: tier - 3 | J1053: =IF(K1053="?","Unknown",K1053) -> R1011 | K1053: R1011 | L1053: =CONCATENATE(E1053,"-",D1053,"-",C1053) -> 6-Nov-1975 | M1053: =DATEDIF(L1053,DATE(2023,6,8),"Y") -> 47
A1054: Id1286 | B1054: ? | C1054: =IF(B1054="?",ROUND(AVERAGE(B:B),0),B1054) -> 1983 | D1054: Dec | E1054: 12 | F1054: 1 | G1054: 8547.69 | H1054: tier - 2 | I1054: tier - 1 | J1054: =IF(K1054="?","Unknown",K1054) -> R1013 | K1054: R1013 | L1054: =CONCATENATE(E1054,"-",D1054,"-",C1054) -> 12-Dec-1983 | M1054: =DATEDIF(L1054,DATE(2023,6,8),"Y") -> 39
A1055: Id1285 | B1055: 1975 | C1055: =IF(B1055="?",ROUND(AVERAGE(B:B),0),B1055) -> 1975 | D1055: Aug | E1055: 6 | F1055: 1 | G1055: 8551.35 | H1055: tier - 2 | I1055: tier - 2 | J1055: =IF(K1055="?","Unknown",K1055) -> R1011 | K1055: R1011 | L1055: =CONCATENATE(E1055,"-",D1055,"-",C1055) -> 6-Aug-1975 | M1055: =DATEDIF(L1055,DATE(2023,6,8),"Y") -> 47
A1056: Id1284 | B1056: 1975 | C1056: =IF(B1056="?",ROUND(AVERAGE(B:B),0),B1056) -> 1975 | D1056: Aug | E1056: 21 | F1056: 1 | G1056: 8556.91 | H1056: tier - 2 | I1056: tier - 1 | J1056: =IF(K1056="?","Unknown",K1056) -> R1011 | K1056: R1011 | L1056: =CONCATENATE(E1056,"-",D1056,"-",C1056) -> 21-Aug-1975 | M1056: =DATEDIF(L1056,DATE(2023,6,8),"Y") -> 47
A1057: Id1283 | B1057: 1988 | C1057: =IF(B1057="?",ROUND(AVERAGE(B:B),0),B1057) -> 1988 | D1057: Sep | E1057: 21 | F1057: 3 | G1057: 8567.25 | H1057: tier - 2 | I1057: tier - 1 | J1057: =IF(K1057="?","Unknown",K1057) -> R1012 | K1057: R1012 | L1057: =CONCATENATE(E1057,"-",D1057,"-",C1057) -> 21-Sep-1988 | M1057: =DATEDIF(L1057,DATE(2023,6,8),"Y") -> 34
A1058: Id1282 | B1058: 1975 | C1058: =IF(B1058="?",ROUND(AVERAGE(B:B),0),B1058) -> 1975 | D1058: Sep | E1058: 26 | F1058: 1 | G1058: 8569.86 | H1058: tier - 2 | I1058: tier - 3 | J1058: =IF(K1058="?","Unknown",K1058) -> R1013 | K1058: R1013 | L1058: =CONCATENATE(E1058,"-",D1058,"-",C1058) -> 26-Sep-1975 | M1058: =DATEDIF(L1058,DATE(2023,6,8),"Y") -> 47
A1059: Id1281 | B1059: 1982 | C1059: =IF(B1059="?",ROUND(AVERAGE(B:B),0),B1059) -> 1982 | D1059: Dec | E1059: 6 | F1059: 3 | G1059: 8572.04 | H1059: tier - 2 | I1059: tier - 2 | J1059: =IF(K1059="?","Unknown",K1059) -> R1021 | K1059: R1021 | L1059: =CONCATENATE(E1059,"-",D1059,"-",C1059) -> 6-Dec-1982 | M1059: =DATEDIF(L1059,DATE(2023,6,8),"Y") -> 40
A1060: Id1280 | B1060: 1987 | C1060: =IF(B1060="?",ROUND(AVERAGE(B:B),0),B1060) -> 1987 | D1060: Nov | E1060: 11 | F1060: 3 | G1060: 8573.3 | H1060: tier - 2 | I1060: tier - 2 | J1060: =IF(K1060="?","Unknown",K1060) -> R1021 | K1060: R1021 | L1060: =CONCATENATE(E1060,"-",D1060,"-",C1060) -> 11-Nov-1987 | M1060: =DATEDIF(L1060,DATE(2023,6,8),"Y") -> 35
A1061: Id1279 | B1061: 1983 | C1061: =IF(B1061="?",ROUND(AVERAGE(B:B),0),B1061) -> 1983 | D1061: Dec | E1061: 30 | F1061: 5 | G1061: 8582.3 | H1061: tier - 2 | I1061: tier - 1 | J1061: =IF(K1061="?","Unknown",K1061) -> R1013 | K1061: R1013 | L1061: =CONCATENATE(E1061,"-",D1061,"-",C1061) -> 30-Dec-1983 | M1061: =DATEDIF(L1061,DATE(2023,6,8),"Y") -> 39
A1062: Id1278 | B1062: 1983 | C1062: =IF(B1062="?",ROUND(AVERAGE(B:B),0),B1062) -> 1983 | D1062: Jul | E1062: 25 | F1062: 5 | G1062: 8596.83 | H1062: tier - 2 | I1062: tier - 3 | J1062: =IF(K1062="?","Unknown",K1062) -> R1013 | K1062: R1013 | L1062: =CONCATENATE(E1062,"-",D1062,"-",C1062) -> 25-Jul-1983 | M1062: =DATEDIF(L1062,DATE(2023,6,8),"Y") -> 39
A1063: Id1277 | B1063: 1973 | C1063: =IF(B1063="?",ROUND(AVERAGE(B:B),0),B1063) -> 1973 | D1063: Jul | E1063: 11 | F1063: 0 | G1063: 8601.33 | H1063: tier - 2 | I1063: tier - 1 | J1063: =IF(K1063="?","Unknown",K1063) -> R1013 | K1063: R1013 | L1063: =CONCATENATE(E1063,"-",D1063,"-",C1063) -> 11-Jul-1973 | M1063: =DATEDIF(L1063,DATE(2023,6,8),"Y") -> 49
A1064: Id1276 | B1064: 1977 | C1064: =IF(B1064="?",ROUND(AVERAGE(B:B),0),B1064) -> 1977 | D1064: Sep | E1064: 24 | F1064: 2 | G1064: 8603.82 | H1064: tier - 2 | I1064: tier - 1 | J1064: =IF(K1064="?","Unknown",K1064) -> R1019 | K1064: R1019 | L1064: =CONCATENATE(E1064,"-",D1064,"-",C1064) -> 24-Sep-1977 | M1064: =DATEDIF(L1064,DATE(2023,6,8),"Y") -> 45
A1065: Id1275 | B1065: 1977 | C1065: =IF(B1065="?",ROUND(AVERAGE(B:B),0),B1065) -> 1977 | D1065: Nov | E1065: 12 | F1065: 2 | G1065: 8604.48 | H1065: tier - 3 | I1065: tier - 2 | J1065: =IF(K1065="?","Unknown",K1065) -> R1016 | K1065: R1016 | L1065: =CONCATENATE(E1065,"-",D1065,"-",C1065) -> 12-Nov-1977 | M1065: =DATEDIF(L1065,DATE(2023,6,8),"Y") -> 45
A1066: Id1274 | B1066: 1977 | C1066: =IF(B1066="?",ROUND(AVERAGE(B:B),0),B1066) -> 1977 | D1066: Oct | E1066: 15 | F1066: 3 | G1066: 8605.36 | H1066: tier - 2 | I1066: tier - 2 | J1066: =IF(K1066="?","Unknown",K1066) -> R1013 | K1066: R1013 | L1066: =CONCATENATE(E1066,"-",D1066,"-",C1066) -> 15-Oct-1977 | M1066: =DATEDIF(L1066,DATE(2023,6,8),"Y") -> 45
... A2344: Id1 | B2344: 1968 | C2344: =IF(B2344="?",ROUND(AVERAGE(B:B),0),B2344) -> 1968 | D2344: Oct | E2344: 12 | F2344: 0 | G2344: 63770.43 | H2344: tier - 1 | I2344: tier - 3 | J2344: =IF(K2344="?","Unknown",K2344) -> R1013 | K2344: R1013 | L2344: =CONCATENATE(E2344,"-",D2344,"-",C2344) -> 12-Oct-1968 | M2344: =DATEDIF(L2344,DATE(2023,6,8),"Y") -> 54

Sheet HealthCare
A1: CustomerID | B1: First Name | C1: BMI | D1: HBA1C | E1: Heart Issues | F1: Any Transplants | G1: Cancer History | H1: Number of major Surgeries | I1: Smoker | J1: Weight Status | K1: Diabetes Status | L1: Date of Birth | M1: Charges | N1: Hospital tier | O1: City tier | P1: State ID | Q1: Age
A2: =VLOOKUP('Customer Names'!A2,'Customer Names'!A:A,1,FALSE) -> Id1 | B2: =VLOOKUP(Table2[[#This Row],[CustomerID]],'Customer Names'!A:E,4,FALSE) -> Kelly | C2: =VLOOKUP(Table2[[#This Row],[CustomerID]],'Medical Examinations'!A:J,2,FALSE) -> 47.41 | D2: =VLOOKUP(Table2[[#This Row],[CustomerID]],'Medical Examinations'!A:J,3,FALSE) -> 7.47 | E2: =VLOOKUP(Table2[[#This Row],[CustomerID]],'Medical Examinations'!A:J,4,FALSE) -> No | F2: =VLOOKUP(Table2[[#This Row],[CustomerID]],'Medical Examinations'!A:J,5,FALSE) -> No | G2: =VLOOKUP(Table2[[#This Row],[CustomerID]],'Medical Examinations'!A:J,6,FALSE) -> No | H2: =VLOOKUP(Table2[[#This Row],[CustomerID]],'Medical Examinations'!A:J,7,FALSE) -> 0 | I2: =VLOOKUP(Table2[[#This Row],[CustomerID]],'Medical Examinations'!A:J,8,FALSE) -> Yes | J2: =VLOOKUP(Table2[[#This Row],[CustomerID]],'Medical Examinations'!A:J,9,FALSE) -> Obesity | K2: =VLOOKUP(Table2[[#This Row],[CustomerID]],'Medical Examinations'!A:J,10,FALSE) -> Diabetes | L2: =VLOOKUP(Table2[[#This Row],[CustomerID]],'Hospitalisation Details'!A:M,12,FALSE) -> 12-Oct-1968 | M2: =VLOOKUP(Table2[[#This Row],[CustomerID]],'Hospitalisation Details'!A:M,7,FALSE) -> 63770.43 | N2: =VLOOKUP(Table2[[#This Row],[CustomerID]],'Hospitalisation Details'!A:M,8,FALSE) -> tier - 1 | O2: =VLOOKUP(Table2[[#This Row],[CustomerID]],'Hospitalisation Details'!A:M,9,FALSE) -> tier - 3 | P2: =VLOOKUP(Table2[[#This Row],[CustomerID]],'Hospitalisation Details'!A:M,10,FALSE) -> R1013 | Q2: =VLOOKUP(Table2[[#This Row],[CustomerID]],'Hospitalisation Details'!A:M,13,FALSE) -> 54
A3: =VLOOKUP('Customer Names'!A3,'Customer Names'!A:A,1,FALSE) -> Id2 | B3: =VLOOKUP(Table2[[#This Row],[CustomerID]],'Customer Names'!A:E,4,FALSE) -> Matthew D | C3: =VLOOKUP(Table2[[#This Row],[CustomerID]],'Medical Examinations'!A:J,2,FALSE) -> 30.36 | D3: =VLOOKUP(Table2[[#This Row],[CustomerID]],'Medical Examinations'!A:J,3,FALSE) -> 5.77 | E3: =VLOOKUP(Table2[[#This Row],[CustomerID]],'Medical Examinations'!A:J,4,FALSE) -> No | F3: =VLOOKUP(Table2[[#This Row],[CustomerID]],'Medical Examinations'!A:J,5,FALSE) -> No | G3: =VLOOKUP(Table2[[#This Row],[CustomerID]],'Medical Examinations'!A:J,6,FALSE) -> No | H3: =VLOOKUP(Table2[[#This Row],[CustomerID]],'Medical Examinations'!A:J,7,FALSE) -> 0 | I3: =VLOOKUP(Table2[[#This Row],[CustomerID]],'Medical Examinations'!A:J,8,FALSE) -> Yes | J3: =VLOOKUP(Table2[[#This Row],[CustomerID]],'Medical Examinations'!A:J,9,FALSE) -> Obesity | K3: =VLOOKUP(Table2[[#This Row],[CustomerID]],'Medical Examinations'!A:J,10,FALSE) -> Prediabetes | L3: =VLOOKUP(Table2[[#This Row],[CustomerID]],'Hospitalisation Details'!A:M,12,FALSE) -> 8-Jun-1977 | M3: =VLOOKUP(Table2[[#This Row],[CustomerID]],'Hospitalisation Details'!A:M,7,FALSE) -> 62592.87 | N3: =VLOOKUP(Table2[[#This Row],[CustomerID]],'Hospitalisation Details'!A:M,8,FALSE) -> tier - 2 | O3: =VLOOKUP(Table2[[#This Row],[CustomerID]],'Hospitalisation Details'!A:M,9,FALSE) -> tier - 3 | P3: =VLOOKUP(Table2[[#This Row],[CustomerID]],'Hospitalisation Details'!A:M,10,FALSE) -> R1013 | Q3: =VLOOKUP(Table2[[#This Row],[CustomerID]],'Hospitalisation Details'!A:M,13,FALSE) -> 46
A4: =VLOOKUP('Customer Names'!A4,'Customer Names'!A:A,1,FALSE) -> Id3 | B4: =VLOOKUP(Table2[[#This Row],[CustomerID]],'Customer Names'!A:E,4,FALSE) -> Phil | C4: =VLOOKUP(Table2[[#This Row],[CustomerID]],'Medical Examinations'!A:J,2,FALSE) -> 34.485 | D4: =VLOOKUP(Table2[[#This Row],[CustomerID]],'Medical Examinations'!A:J,3,FALSE) -> 11.87 | E4: =VLOOKUP(Table2[[#This Row],[CustomerID]],'Medical Examinations'!A:J,4,FALSE) -> Yes | F4: =VLOOKUP(Table2[[#This Row],[CustomerID]],'Medical Examinations'!A:J,5,FALSE) -> No | G4: =VLOOKUP(Table2[[#This Row],[CustomerID]],'Medical Examinations'!A:J,6,FALSE) -> No | H4: =VLOOKUP(Table2[[#This Row],[CustomerID]],'Medical Examinations'!A:J,7,FALSE) -> 2 | I4: =VLOOKUP(Table2[[#This Row],[CustomerID]],'Medical Examinations'!A:J,8,FALSE) -> Yes | J4: =VLOOKUP(Table2[[#This Row],[CustomerID]],'Medical Examinations'!A:J,9,FALSE) -> Obesity | K4: =VLOOKUP(Table2[[#This Row],[CustomerID]],'Medical Examinations'!A:J,10,FALSE) -> Diabetes | L4: =VLOOKUP(Table2[[#This Row],[CustomerID]],'Hospitalisation Details'!A:M,12,FALSE) -> 11-Sep-1970 | M4: =VLOOKUP(Table2[[#This Row],[CustomerID]],'Hospitalisation Details'!A:M,7,FALSE) -> 60021.4 | N4: =VLOOKUP(Table2[[#This Row],[CustomerID]],'Hospitalisation Details'!A:M,8,FALSE) -> tier - 1 | O4: =VLOOKUP(Table2[[#This Row],[CustomerID]],'Hospitalisation Details'!A:M,9,FALSE) -> tier - 1 | P4: =VLOOKUP(Table2[[#This Row],[CustomerID]],'Hospitalisation Details'!A:M,10,FALSE) -> R1012 | Q4: =VLOOKUP(Table2[[#This Row],[CustomerID]],'Hospitalisation Details'!A:M,13,FALSE) -> 52
A5: =VLOOKUP('Customer Names'!A5,'Customer Names'!A:A,1,FALSE) -> Id4 | B5: =VLOOKUP(Table2[[#This Row],[CustomerID]],'Customer Names'!A:E,4,FALSE) -> Kelsey | C5: =VLOOKUP(Table2[[#This Row],[CustomerID]],'Medical Examinations'!A:J,2,FALSE) -> 38.095 | D5: =VLOOKUP(Table2[[#This Row],[CustomerID]],'Medical Examinations'!A:J,3,FALSE) -> 6.05 | E5: =VLOOKUP(Table2[[#This Row],[CustomerID]],'Medical Examinations'!A:J,4,FALSE) -> No | F5: =VLOOKUP(Table2[[#This Row],[CustomerID]],'Medical Examinations'!A:J,5,FALSE) -> No | G5: =VLOOKUP(Table2[[#This Row],[CustomerID]],'Medical Examinations'!A:J,6,FALSE) -> No | H5: =VLOOKUP(Table2[[#This Row],[CustomerID]],'Medical Examinations'!A:J,7,FALSE) -> 0 | I5: =VLOOKUP(Table2[[#This Row],[CustomerID]],'Medical Examinations'!A:J,8,FALSE) -> Yes | J5: =VLOOKUP(Table2[[#This Row],[CustomerID]],'Medical Examinations'!A:J,9,FALSE) -> Obesity | K5: =VLOOKUP(Table2[[#This Row],[CustomerID]],'Medical Examinations'!A:J,10,FALSE) -> Prediabetes | L5: =VLOOKUP(Table2[[#This Row],[CustomerID]],'Hospitalisation Details'!A:M,12,FALSE) -> 6-Jun-1991 | M5: =VLOOKUP(Table2[[#This Row],[CustomerID]],'Hospitalisation Details'!A:M,7,FALSE) -> 58571.07 | N5: =VLOOKUP(Table2[[#This Row],[CustomerID]],'Hospitalisation Details'!A:M,8,FALSE) -> tier - 1 | O5: =VLOOKUP(Table2[[#This Row],[CustomerID]],'Hospitalisation Details'!A:M,9,FALSE) -> tier - 3 | P5: =VLOOKUP(Table2[[#This Row],[CustomerID]],'Hospitalisation Details'!A:M,10,FALSE) -> R1024 | Q5: =VLOOKUP(Table2[[#This Row],[CustomerID]],'Hospitalisation Details'!A:M,13,FALSE) -> 32
A6: =VLOOKUP('Customer Names'!A6,'Customer Names'!A:A,1,FALSE) -> Id5 | B6: =VLOOKUP(Table2[[#This Row],[CustomerID]],'Customer Names'!A:E,4,FALSE) -> Kristyn | C6: =VLOOKUP(Table2[[#This Row],[CustomerID]],'Medical Examinations'!A:J,2,FALSE) -> 35.53 | D6: =VLOOKUP(Table2[[#This Row],[CustomerID]],'Medical Examinations'!A:J,3,FALSE) -> 5.45 | E6: =VLOOKUP(Table2[[#This Row],[CustomerID]],'Medical Examinations'!A:J,4,FALSE) -> No | F6: =VLOOKUP(Table2[[#This Row],[CustomerID]],'Medical Examinations'!A:J,5,FALSE) -> No | G6: =VLOOKUP(Table2[[#This Row],[CustomerID]],'Medical Examinations'!A:J,6,FALSE) -> No | H6: =VLOOKUP(Table2[[#This Row],[CustomerID]],'Medical Examinations'!A:J,7,FALSE) -> 0 | I6: =VLOOKUP(Table2[[#This Row],[CustomerID]],'Medical Examinations'!A:J,8,FALSE) -> Yes | J6: =VLOOKUP(Table2[[#This Row],[CustomerID]],'Medical Examinations'!A:J,9,FALSE) -> Obesity | K6: =VLOOKUP(Table2[[#This Row],[CustomerID]],'Medical Examinations'!A:J,10,FALSE) -> Normal | L6: =VLOOKUP(Table2[[#This Row],[CustomerID]],'Hospitalisation Details'!A:M,12,FALSE) -> 19-Jun-1989 | M6: =VLOOKUP(Table2[[#This Row],[CustomerID]],'Hospitalisation Details'!A:M,7,FALSE) -> 55135.4 | N6: =VLOOKUP(Table2[[#This Row],[CustomerID]],'Hospitalisation Details'!A:M,8,FALSE) -> tier - 1 | O6: =VLOOKUP(Table2[[#This Row],[CustomerID]],'Hospitalisation Details'!A:M,9,FALSE) -> tier - 2 | P6: =VLOOKUP(Table2[[#This Row],[CustomerID]],'Hospitalisation Details'!A:M,10,FALSE) -> R1012 | Q6: =VLOOKUP(Table2[[#This Row],[CustomerID]],'Hospitalisation Details'!A:M,13,FALSE) -> 33
A7: =VLOOKUP('Customer Names'!A7,'Customer Names'!A:A,1,FALSE) -> Id6 | B7: =VLOOKUP(Table2[[#This Row],[CustomerID]],'Customer Names'!A:E,4,FALSE) -> Russell B | C7: =VLOOKUP(Table2[[#This Row],[CustomerID]],'Medical Examinations'!A:J,2,FALSE) -> 32.8 | D7: =VLOOKUP(Table2[[#This Row],[CustomerID]],'Medical Examinations'!A:J,3,FALSE) -> 6.59 | E7: =VLOOKUP(Table2[[#This Row],[CustomerID]],'Medical Examinations'!A:J,4,FALSE) -> No | F7: =VLOOKUP(Table2[[#This Row],[CustomerID]],'Medical Examinations'!A:J,5,FALSE) -> No | G7: =VLOOKUP(Table2[[#This Row],[CustomerID]],'Medical Examinations'!A:J,6,FALSE) -> No | H7: =VLOOKUP(Table2[[#This Row],[CustomerID]],'Medical Examinations'!A:J,7,FALSE) -> 0 | I7: =VLOOKUP(Table2[[#This Row],[CustomerID]],'Medical Examinations'!A:J,8,FALSE) -> Yes | J7: =VLOOKUP(Table2[[#This Row],[CustomerID]],'Medical Examinations'!A:J,9,FALSE) -> Obesity | K7: =VLOOKUP(Table2[[#This Row],[CustomerID]],'Medical Examinations'!A:J,10,FALSE) -> Diabetes | L7: =VLOOKUP(Table2[[#This Row],[CustomerID]],'Hospitalisation Details'!A:M,12,FALSE) -> 4-Aug-1962 | M7: =VLOOKUP(Table2[[#This Row],[CustomerID]],'Hospitalisation Details'!A:M,7,FALSE) -> 52590.83 | N7: =VLOOKUP(Table2[[#This Row],[CustomerID]],'Hospitalisation Details'!A:M,8,FALSE) -> tier - 1 | O7: =VLOOKUP(Table2[[#This Row],[CustomerID]],'Hospitalisation Details'!A:M,9,FALSE) -> tier - 3 | P7: =VLOOKUP(Table2[[#This Row],[CustomerID]],'Hospitalisation Details'!A:M,10,FALSE) -> R1011 | Q7: =VLOOKUP(Table2[[#This Row],[CustomerID]],'Hospitalisation Details'!A:M,13,FALSE) -> 60
A8: =VLOOKUP('Customer Names'!A8,'Customer Names'!A:A,1,FALSE) -> Id7 | B8: =VLOOKUP(Table2[[#This Row],[CustomerID]],'Customer Names'!A:E,4,FALSE) -> Scott | C8: =VLOOKUP(Table2[[#This Row],[CustomerID]],'Medical Examinations'!A:J,2,FALSE) -> 36.4 | D8: =VLOOKUP(Table2[[#This Row],[CustomerID]],'Medical Examinations'!A:J,3,FALSE) -> 6.07 | E8: =VLOOKUP(Table2[[#This Row],[CustomerID]],'Medical Examinations'!A:J,4,FALSE) -> No | F8: =VLOOKUP(Table2[[#This Row],[CustomerID]],'Medical Examinations'!A:J,5,FALSE) -> No | G8: =VLOOKUP(Table2[[#This Row],[CustomerID]],'Medical Examinations'!A:J,6,FALSE) -> No | H8: =VLOOKUP(Table2[[#This Row],[CustomerID]],'Medical Examinations'!A:J,7,FALSE) -> 0 | I8: =VLOOKUP(Table2[[#This Row],[CustomerID]],'Medical Examinations'!A:J,8,FALSE) -> Yes | J8: =VLOOKUP(Table2[[#This Row],[CustomerID]],'Medical Examinations'!A:J,9,FALSE) -> Obesity | K8: =VLOOKUP(Table2[[#This Row],[CustomerID]],'Medical Examinations'!A:J,10,FALSE) -> Prediabetes | L8: =VLOOKUP(Table2[[#This Row],[CustomerID]],'Hospitalisation Details'!A:M,12,FALSE) -> 27-Oct-1994 | M8: =VLOOKUP(Table2[[#This Row],[CustomerID]],'Hospitalisation Details'!A:M,7,FALSE) -> 51194.56 | N8: =VLOOKUP(Table2[[#This Row],[CustomerID]],'Hospitalisation Details'!A:M,8,FALSE) -> tier - 1 | O8: =VLOOKUP(Table2[[#This Row],[CustomerID]],'Hospitalisation Details'!A:M,9,FALSE) -> tier - 3 | P8: =VLOOKUP(Table2[[#This Row],[CustomerID]],'Hospitalisation Details'!A:M,10,FALSE) -> R1011 | Q8: =VLOOKUP(Table2[[#This Row],[CustomerID]],'Hospitalisation Details'!A:M,13,FALSE) -> 28
A9: =VLOOKUP('Customer Names'!A9,'Customer Names'!A:A,1,FALSE) -> Id8 | B9: =VLOOKUP(Table2[[#This Row],[CustomerID]],'Customer Names'!A:E,4,FALSE) -> Stephen | C9: =VLOOKUP(Table2[[#This Row],[CustomerID]],'Medical Examinations'!A:J,2,FALSE) -> 36.96 | D9: =VLOOKUP(Table2[[#This Row],[CustomerID]],'Medical Examinations'!A:J,3,FALSE) -> 7.93 | E9: =VLOOKUP(Table2[[#This Row],[CustomerID]],'Medical Examinations'!A:J,4,FALSE) -> No | F9: =VLOOKUP(Table2[[#This Row],[CustomerID]],'Medical Examinations'!A:J,5,FALSE) -> No | G9: =VLOOKUP(Table2[[#This Row],[CustomerID]],'Medical Examinations'!A:J,6,FALSE) -> No | H9: =VLOOKUP(Table2[[#This Row],[CustomerID]],'Medical Examinations'!A:J,7,FALSE) -> 3 | I9: =VLOOKUP(Table2[[#This Row],[CustomerID]],'Medical Examinations'!A:J,8,FALSE) -> Yes | J9: =VLOOKUP(Table2[[#This Row],[CustomerID]],'Medical Examinations'!A:J,9,FALSE) -> Obesity | K9: =VLOOKUP(Table2[[#This Row],[CustomerID]],'Medical Examinations'!A:J,10,FALSE) -> Diabetes | L9: =VLOOKUP(Table2[[#This Row],[CustomerID]],'Hospitalisation Details'!A:M,12,FALSE) -> 27-Jun-1958 | M9: =VLOOKUP(Table2[[#This Row],[CustomerID]],'Hospitalisation Details'!A:M,7,FALSE) -> 49577.66 | N9: =VLOOKUP(Table2[[#This Row],[CustomerID]],'Hospitalisation Details'!A:M,8,FALSE) -> tier - 2 | O9: =VLOOKUP(Table2[[#This Row],[CustomerID]],'Hospitalisation Details'!A:M,9,FALSE) -> tier - 2 | P9: =VLOOKUP(Table2[[#This Row],[CustomerID]],'Hospitalisation Details'!A:M,10,FALSE) -> R1013 | Q9: =VLOOKUP(Table2[[#This Row],[CustomerID]],'Hospitalisation Details'!A:M,13,FALSE) -> 64
A10: =VLOOKUP('Customer Names'!A10,'Customer Names'!A:A,1,FALSE) -> Id9 | B10: =VLOOKUP(Table2[[#This Row],[CustomerID]],'Customer Names'!A:E,4,FALSE) -> Patrick R | C10: =VLOOKUP(Table2[[#This Row],[CustomerID]],'Medical Examinations'!A:J,2,FALSE) -> 41.14 | D10: =VLOOKUP(Table2[[#This Row],[CustomerID]],'Medical Examinations'!A:J,3,FALSE) -> 9.58 | E10: =VLOOKUP(Table2[[#This Row],[CustomerID]],'Medical Examinations'!A:J,4,FALSE) -> Yes | F10: =VLOOKUP(Table2[[#This Row],[CustomerID]],'Medical Examinations'!A:J,5,FALSE) -> No | G10: =VLOOKUP(Table2[[#This Row],[CustomerID]],'Medical Examinations'!A:J,6,FALSE) -> Yes | H10: =VLOOKUP(Table2[[#This Row],[CustomerID]],'Medical Examinations'!A:J,7,FALSE) -> 1 | I10: =VLOOKUP(Table2[[#This Row],[CustomerID]],'Medical Examinations'!A:J,8,FALSE) -> Yes | J10: =VLOOKUP(Table2[[#This Row],[CustomerID]],'Medical Examinations'!A:J,9,FALSE) -> Obesity | K10: =VLOOKUP(Table2[[#This Row],[CustomerID]],'Medical Examinations'!A:J,10,FALSE) -> Diabetes | L10: =VLOOKUP(Table2[[#This Row],[CustomerID]],'Hospitalisation Details'!A:M,12,FALSE) -> 4-Sep-1963 | M10: =VLOOKUP(Table2[[#This Row],[CustomerID]],'Hospitalisation Details'!A:M,7,FALSE) -> 48970.25 | N10: =VLOOKUP(Table2[[#This Row],[CustomerID]],'Hospitalisation Details'!A:M,8,FALSE) -> tier - 1 | O10: =VLOOKUP(Table2[[#This Row],[CustomerID]],'Hospitalisation Details'!A:M,9,FALSE) -> tier - 2 | P10: =VLOOKUP(Table2[[#This Row],[CustomerID]],'Hospitalisation Details'!A:M,10,FALSE) -> R1013 | Q10: =VLOOKUP(Table2[[#This Row],[CustomerID]],'Hospitalisation Details'!A:M,13,FALSE) -> 59
A11: =VLOOKUP('Customer Names'!A11,'Customer Names'!A:A,1,FALSE) -> Id10 | B11: =VLOOKUP(Table2[[#This Row],[CustomerID]],'Customer Names'!A:E,4,FALSE) -> Brooke N | C11: =VLOOKUP(Table2[[#This Row],[CustomerID]],'Medical Examinations'!A:J,2,FALSE) -> 38.06 | D11: =VLOOKUP(Table2[[#This Row],[CustomerID]],'Medical Examinations'!A:J,3,FALSE) -> 10.79 | E11: =VLOOKUP(Table2[[#This Row],[CustomerID]],'Medical Examinations'!A:J,4,FALSE) -> No | F11: =VLOOKUP(Table2[[#This Row],[CustomerID]],'Medical Examinations'!A:J,5,FALSE) -> No | G11: =VLOOKUP(Table2[[#This Row],[CustomerID]],'Medical Examinations'!A:J,6,FALSE) -> No | H11: =VLOOKUP(Table2[[#This Row],[CustomerID]],'Medical Examinations'!A:J,7,FALSE) -> 0 | I11: =VLOOKUP(Table2[[#This Row],[CustomerID]],'Medical Examinations'!A:J,8,FALSE) -> Yes | J11: =VLOOKUP(Table2[[#This Row],[CustomerID]],'Medical Examinations'!A:J,9,FALSE) -> Obesity | K11: =VLOOKUP(Table2[[#This Row],[CustomerID]],'Medical Examinations'!A:J,10,FALSE) -> Diabetes | L11: =VLOOKUP(Table2[[#This Row],[CustomerID]],'Hospitalisation Details'!A:M,12,FALSE) -> 29-Dec-1978 | M11: =VLOOKUP(Table2[[#This Row],[CustomerID]],'Hospitalisation Details'!A:M,7,FALSE) -> 48885.14 | N11: =VLOOKUP(Table2[[#This Row],[CustomerID]],'Hospitalisation Details'!A:M,8,FALSE) -> tier - 1 | O11: =VLOOKUP(Table2[[#This Row],[CustomerID]],'Hospitalisation Details'!A:M,9,FALSE) -> tier - 2 | P11: =VLOOKUP(Table2[[#This Row],[CustomerID]],'Hospitalisation Details'!A:M,10,FALSE) -> R1013 | Q11: =VLOOKUP(Table2[[#This Row],[CustomerID]],'Hospitalisation Details'!A:M,13,FALSE) -> 44
A12: =VLOOKUP('Customer Names'!A12,'Customer Names'!A:A,1,FALSE) -> Id11 | B12: =VLOOKUP(Table2[[#This Row],[CustomerID]],'Customer Names'!A:E,4,FALSE) -> Paola Andrea | C12: =VLOOKUP(Table2[[#This Row],[CustomerID]],'Medical Examinations'!A:J,2,FALSE) -> 37.7 | D12: =VLOOKUP(Table2[[#This Row],[CustomerID]],'Medical Examinations'!A:J,3,FALSE) -> 5.96 | E12: =VLOOKUP(Table2[[#This Row],[CustomerID]],'Medical Examinations'!A:J,4,FALSE) -> Yes | F12: =VLOOKUP(Table2[[#This Row],[CustomerID]],'Medical Examinations'!A:J,5,FALSE) -> No | G12: =VLOOKUP(Table2[[#This Row],[CustomerID]],'Medical Examinations'!A:J,6,FALSE) -> No | H12: =VLOOKUP(Table2[[#This Row],[CustomerID]],'Medical Examinations'!A:J,7,FALSE) -> 2 | I12: =VLOOKUP(Table2[[#This Row],[CustomerID]],'Medical Examinations'!A:J,8,FALSE) -> Yes | J12: =VLOOKUP(Table2[[#This Row],[CustomerID]],'Medical Examinations'!A:J,9,FALSE) -> Obesity | K12: =VLOOKUP(Table2[[#This Row],[CustomerID]],'Medical Examinations'!A:J,10,FALSE) -> Prediabetes | L12: =VLOOKUP(Table2[[#This Row],[CustomerID]],'Hospitalisation Details'!A:M,12,FALSE) -> 22-Jul-1959 | M12: =VLOOKUP(Table2[[#This Row],[CustomerID]],'Hospitalisation Details'!A:M,7,FALSE) -> 48824.45 | N12: =VLOOKUP(Table2[[#This Row],[CustomerID]],'Hospitalisation Details'!A:M,8,FALSE) -> tier - 2 | O12: =VLOOKUP(Table2[[#This Row],[CustomerID]],'Hospitalisation Details'!A:M,9,FALSE) -> tier - 1 | P12: =VLOOKUP(Table2[[#This Row],[CustomerID]],'Hospitalisation Details'!A:M,10,FALSE) -> R1011 | Q12: =VLOOKUP(Table2[[#This Row],[CustomerID]],'Hospitalisation Details'!A:M,13,FALSE) -> 63
A13: =VLOOKUP('Customer Names'!A13,'Customer Names'!A:A,1,FALSE) -> Id12 | B13: =VLOOKUP(Table2[[#This Row],[CustomerID]],'Customer Names'!A:E,4,FALSE) -> David | C13: =VLOOKUP(Table2[[#This Row],[CustomerID]],'Medical Examinations'!A:J,2,FALSE) -> 42.13 | D13: =VLOOKUP(Table2[[#This Row],[CustomerID]],'Medical Examinations'!A:J,3,FALSE) -> 11.9 | E13: =VLOOKUP(Table2[[#This Row],[CustomerID]],'Medical Examinations'!A:J,4,FALSE) -> No | F13: =VLOOKUP(Table2[[#This Row],[CustomerID]],'Medical Examinations'!A:J,5,FALSE) -> No | G13: =VLOOKUP(Table2[[#This Row],[CustomerID]],'Medical Examinations'!A:J,6,FALSE) -> No | H13: =VLOOKUP(Table2[[#This Row],[CustomerID]],'Medical Examinations'!A:J,7,FALSE) -> 0 | I13: =VLOOKUP(Table2[[#This Row],[CustomerID]],'Medical Examinations'!A:J,8,FALSE) -> Yes | J13: =VLOOKUP(Table2[[#This Row],[CustomerID]],'Medical Examinations'!A:J,9,FALSE) -> Obesity | K13: =VLOOKUP(Table2[[#This Row],[CustomerID]],'Medical Examinations'!A:J,10,FALSE) -> Diabetes | L13: =VLOOKUP(Table2[[#This Row],[CustomerID]],'Hospitalisation Details'!A:M,12,FALSE) -> 27-Oct-1965 | M13: =VLOOKUP(Table2[[#This Row],[CustomerID]],'Hospitalisation Details'!A:M,7,FALSE) -> 48675.52 | N13: =VLOOKUP(Table2[[#This Row],[CustomerID]],'Hospitalisation Details'!A:M,8,FALSE) -> tier - 1 | O13: =VLOOKUP(Table2[[#This Row],[CustomerID]],'Hospitalisation Details'!A:M,9,FALSE) -> tier - 2 | P13: =VLOOKUP(Table2[[#This Row],[CustomerID]],'Hospitalisation Details'!A:M,10,FALSE) -> R1013 | Q13: =VLOOKUP(Table2[[#This Row],[CustomerID]],'Hospitalisation Details'!A:M,13,FALSE) -> 57
... A2336: =VLOOKUP('Customer Names'!A2336,'Customer Names'!A:A,1,FALSE) -> Id2335 | B2336: =VLOOKUP(Table2[[#This Row],[CustomerID]],'Customer Names'!A:E,4,FALSE) -> Aaron K | C2336: =VLOOKUP(Table2[[#This Row],[CustomerID]],'Medical Examinations'!A:J,2,FALSE) -> 17.58 | D2336: =VLOOKUP(Table2[[#This Row],[CustomerID]],'Medical Examinations'!A:J,3,FALSE) -> 4.51 | E2336: =VLOOKUP(Table2[[#This Row],[CustomerID]],'Medical Examinations'!A:J,4,FALSE) -> No | F2336: =VLOOKUP(Table2[[#This Row],[CustomerID]],'Medical Examinations'!A:J,5,FALSE) -> No | G2336: =VLOOKUP(Table2[[#This Row],[CustomerID]],'Medical Examinations'!A:J,6,FALSE) -> No | H2336: =VLOOKUP(Table2[[#This Row],[CustomerID]],'Medical Examinations'!A:J,7,FALSE) -> 1 | I2336: =VLOOKUP(Table2[[#This Row],[CustomerID]],'Medical Examinations'!A:J,8,FALSE) -> No | J2336: =VLOOKUP(Table2[[#This Row],[CustomerID]],'Medical Examinations'!A:J,9,FALSE) -> 0 | K2336: =VLOOKUP(Table2[[#This Row],[CustomerID]],'Medical Examinations'!A:J,10,FALSE) -> 0 | L2336: =VLOOKUP(Table2[[#This Row],[CustomerID]],'Hospitalisation Details'!A:M,12,FALSE) -> 9-Jul-1992 | M2336: =VLOOKUP(Table2[[#This Row],[CustomerID]],'Hospitalisation Details'!A:M,7,FALSE) -> 563.84 | N2336: =VLOOKUP(Table2[[#This Row],[CustomerID]],'Hospitalisation Details'!A:M,8,FALSE) -> tier - 2 | O2336: =VLOOKUP(Table2[[#This Row],[CustomerID]],'Hospitalisation Details'!A:M,9,FALSE) -> tier - 3 | P2336: =VLOOKUP(Table2[[#This Row],[CustomerID]],'Hospitalisation Details'!A:M,10,FALSE) -> R1013 | Q2336: =VLOOKUP(Table2[[#This Row],[CustomerID]],'Hospitalisation Details'!A:M,13,FALSE) -> 30

Sheet Pivot Tables
A3: Count of Cancer History | B3: Column Labels
A4: Row Labels | B4: No | C4: Yes | D4: Grand Total
A5: No | B5: 1334 | C5: 248 | D5: 1582
A6: Yes | B6: 404 | C6: 84 | D6: 488
A7: Grand Total | B7: 1738 | C7: 332 | D7: 2070
A14: Row Labels | B14: Sum of Number of major Surgeries | C14: Average of HBA1C
A15: No | B15: 1319 | C15: 6.7436595
A16: yes | B16: 80 | C16: 5.1701493
A17: Grand Total | B17: 1399 | C17: 6.6927295
A23: Sum of Number of major Surgeries
A24: 1399 | C24: =GETPIVOTDATA("Number of major Surgeries",$A$23) -> 1399
A26: Average of BMI
A27: 31.634773 | C27: =GETPIVOTDATA("BMI",$A$26) -> 31.634773
A28: #VALUE!
A30: Min of Age
A31: 18 | C31: =GETPIVOTDATA("Age",$A$30) -> 18
A42: Sum of Charges
A43: Row Labels | B43: Diabetes | C43: Normal | D43: Prediabetes | E43: Grand Total
A44: NormalWeight | B44: 1714193.7 | C44: 1597416.5 | D44: 807630.05 | E44: 4119240.2
A45: Obesity | B45: 8348618.9 | C45: 8445284 | D45: 3578383.1 | E45: 20372286
A46: OverWeight | B46: 2141178.8 | C46: 2401893.4 | D46: 979339.65 | E46: 5522411.8
A47: UnderWeight | B47: 480739.85 | C47: 521853.65 | D47: 144213.94 | E47: 1146807.4
A48: Grand Total | B48: 12684731 | C48: 12966448 | D48: 5509566.8 | E48: 31160746
A51: Average of Charges
A52: Row Labels | B52: tier - 1 | C52: tier - 2 | D52: tier - 3 | E52: Grand Total
A53: R1011 | B53: 33081.374 | C53: 18997.281 | D53: 9250.3618 | E53: 19466.246
A54: R1012 | B54: 26111.458 | C54: 10334.279 | D54: 10179.942 | E54: 12016.474
A55: R1013 | B55: 31328.102 | C55: 8439.2844 | D55: 6890.7568 | E55: 10514.94
A56: R1014 | B56: 13891.86 | C56: 2395.17 | D56: 16950.485 | E56: 13478.057
A57: R1015 | B57: 21523.52 | C57: 15675.543 | D57: 7570.755 | E57: 13948.61
A58: R1016 | B58: 39868.616 | C58: 16075.963 | D58: 8133.0084 | E58: 13589.263
A59: R1017 | B59: 34070.596 | C59: 11365.622 | D59: 8667.3662 | E59: 14806.108
A60: R1018 | B60: 33475.82 | C60: 10139.553 | D60: 12570.97 | E60: 13272.787
A61: R1019 | B61: 27621.61 | C61: 8116.72 | D61: 12706.976 | E61: 13633.143
A62: R1020 | C62: 6760.5433 | D62: 11716.453 | E62: 9238.4983
A63: R1021 | C63: 7668.1787 | D63: 11518.786 | E63: 8933.3781
A64: R1022 | C64: 10102.027 | D64: 11637.812 | E64: 10650.521
A65: R1023 | B65: 18261.757 | C65: 13457.095 | D65: 12785.637 | E65: 13786.149
A66: R1024 | B66: 32732.187 | C66: 10174.346 | D66: 13360.979 | E66: 12865.149
A67: R1025 | C67: 6886.0368 | D67: 10510.314 | E67: 8788.7823
...

Sheet Dashboard
